Workbook

Sheet Order Summary
B2: ESTHEMAX — ORDER SUMMARY (with monthly sales)
B3: Monthly sales (Apr-25 to Jun-26) | Required = 6-mo avg x (3 derma + 1.5 salon) | Landing = EXW + Customs 44% + Transport
B5: Derma months | D5: 3 | F5: USD to INR | H5: 96.99
B6: Salon months | D6: 1.5 | F6: Customs rate | H6: 0.44
B9: Item | C9: Category | D9: Apr-25 | E9: May-25 | F9: Jun-25 | G9: Jul-25 | H9: Aug-25 | I9: Sep-25 | J9: Oct-25 | K9: Nov-25 | L9: Dec-25 | M9: Jan-26 | N9: Feb-26 | O9: Mar-26 | P9: Apr-26 | Q9: May-26 | R9: Jun-26 | S9: 6-Mo Avg | T9: Derma Req (x3) | U9: Salon Req (x1.5) | V9: Required Stock | W9: Current Stock | X9: To Buy | Y9: Unit $ USD | Z9: EXW INR | AA9: Customs 44% | AB9: Transport | AC9: Landing /Unit | AD9: Money Required
B10: ILLUMINATING ORANGE HYDROJELLY MASK 850gm | C10: ='Order Calculation'!B3 -> JAR | D10: ='Order Calculation'!C3 -> 5 | E10: ='Order Calculation'!D3 -> 70 | F10: ='Order Calculation'!E3 -> 38 | G10: ='Order Calculation'!F3 -> 18 | H10: ='Order Calculation'!G3 -> 41 | I10: ='Order Calculation'!H3 -> 19 | J10: ='Order Calculation'!I3 -> 13 | ... R10: ='Order Calculation'!Q3 -> 55 | S10: ='Order Calculation'!V3/6 -> 36.5 | T10: =S10*$D$5 -> 109.5 | U10: =S10*$D$6 -> 54.75 | V10: =ROUNDUP(T10+U10,0) -> 165 | W10: ='Order Calculation'!Y3 -> 28 | X10: =MAX(0,V10-W10) -> 137 | Y10: 13.8 | Z10: =Y10*$H$5 -> 1338.462 | AA10: =Z10*$H$6 -> 588.92328 | AB10: 66.93 | AC10: =Z10+AA10+AB10 -> 1994.3153 | AD10: =X10*AC10 -> 273221.19
B11: EGYPTIAN ROSE HYDROJELLY MASK 850gm | C11: ='Order Calculation'!B4 -> JAR | D11: ='Order Calculation'!C4 -> 9 | E11: ='Order Calculation'!D4 -> 86 | F11: ='Order Calculation'!E4 -> 32 | G11: ='Order Calculation'!F4 -> 60 | H11: ='Order Calculation'!G4 -> 14 | I11: ='Order Calculation'!H4 -> 31 | J11: ='Order Calculation'!I4 -> 22 | ... R11: ='Order Calculation'!Q4 -> 32 | S11: ='Order Calculation'!V4/6 -> 38.333333 | T11: =S11*$D$5 -> 115 | U11: =S11*$D$6 -> 57.5 | V11: =ROUNDUP(T11+U11,0) -> 173 | W11: ='Order Calculation'!Y4 -> 64 | X11: =MAX(0,V11-W11) -> 109 | Y11: 13.8 | Z11: =Y11*$H$5 -> 1338.462 | AA11: =Z11*$H$6 -> 588.92328 | AB11: 66.93 | AC11: =Z11+AA11+AB11 -> 1994.3153 | AD11: =X11*AC11 -> 217380.37
B12: YOUTHFUL ELIXIR HYDROJELLY MASK 850gm | C12: ='Order Calculation'!B13 -> JAR | D12: ='Order Calculation'!C13 -> 34 | E12: ='Order Calculation'!D13 -> 36 | F12: ='Order Calculation'!E13 -> 16 | G12: ='Order Calculation'!F13 -> 38 | H12: ='Order Calculation'!G13 -> 23 | I12: ='Order Calculation'!H13 -> 5 | J12: ='Order Calculation'!I13 -> 6 | ... R12: ='Order Calculation'!Q13 -> 21 | S12: ='Order Calculation'!V13/6 -> 19.5 | T12: =S12*$D$5 -> 58.5 | U12: =S12*$D$6 -> 29.25 | V12: =ROUNDUP(T12+U12,0) -> 88 | W12: ='Order Calculation'!Y13 -> 57 | X12: =MAX(0,V12-W12) -> 31 | Y12: 24 | Z12: =Y12*$H$5 -> 2327.76 | AA12: =Z12*$H$6 -> 1024.2144 | AB12: 66.93 | AC12: =Z12+AA12+AB12 -> 3418.9044 | AD12: =X12*AC12 -> 105986.04
B13: INTENSIVE AFTERCARE HYDROJELLY MASK 850gm | C13: ='Order Calculation'!B7 -> JAR | D13: ='Order Calculation'!C7 -> 2 | E13: ='Order Calculation'!D7 -> 20 | F13: ='Order Calculation'!E7 -> 17 | G13: ='Order Calculation'!F7 -> 22 | H13: ='Order Calculation'!G7 -> 12 | I13: ='Order Calculation'!H7 -> 23 | J13: ='Order Calculation'!I7 -> 4 | ... R13: ='Order Calculation'!Q7 -> 11 | S13: ='Order Calculation'!V7/6 -> 11.666667 | T13: =S13*$D$5 -> 35 | U13: =S13*$D$6 -> 17.5 | V13: =ROUNDUP(T13+U13,0) -> 53 | W13: ='Order Calculation'!Y7 -> 1 | X13: =MAX(0,V13-W13) -> 52 | Y13: 13.8 | Z13: =Y13*$H$5 -> 1338.462 | AA13: =Z13*$H$6 -> 588.92328 | AB13: 66.93 | AC13: =Z13+AA13+AB13 -> 1994.3153 | AD13: =X13*AC13 -> 103704.39
B14: BELGIUM CACAO HYDROJELLY MASK 850gm | C14: ='Order Calculation'!B8 -> JAR | D14: ='Order Calculation'!C8 -> 17 | E14: ='Order Calculation'!D8 -> 9 | F14: ='Order Calculation'!E8 -> 20 | G14: ='Order Calculation'!F8 -> 5 | H14: ='Order Calculation'!G8 -> 15 | I14: ='Order Calculation'!H8 -> 1 | J14: ='Order Calculation'!I8 -> 3 | ... R14: ='Order Calculation'!Q8 -> 4 | S14: ='Order Calculation'!V8/6 -> 10.166667 | T14: =S14*$D$5 -> 30.5 | U14: =S14*$D$6 -> 15.25 | V14: =ROUNDUP(T14+U14,0) -> 46 | W14: ='Order Calculation'!Y8 -> 5 | X14: =MAX(0,V14-W14) -> 41 | Y14: 13.8 | Z14: =Y14*$H$5 -> 1338.462 | AA14: =Z14*$H$6 -> 588.92328 | AB14: 66.93 | AC14: =Z14+AA14+AB14 -> 1994.3153 | AD14: =X14*AC14 -> 81766.926
B15: BRIGHTENING COMPLEX HYDROJELLY MASK 850gm | C15: ='Order Calculation'!B18 -> JAR | D15: ='Order Calculation'!C18 -> 5 | E15: ='Order Calculation'!D18 -> 53 | F15: ='Order Calculation'!E18 -> 25 | G15: ='Order Calculation'!F18 -> 35 | H15: ='Order Calculation'!G18 -> 20 | I15: ='Order Calculation'!H18 -> 36 | J15: ='Order Calculation'!I18 -> 12 | ... R15: ='Order Calculation'!Q18 -> 10 | S15: ='Order Calculation'!V18/6 -> 27.666667 | T15: =S15*$D$5 -> 83 | U15: =S15*$D$6 -> 41.5 | V15: =ROUNDUP(T15+U15,0) -> 125 | W15: ='Order Calculation'!Y18 -> 89 | X15: =MAX(0,V15-W15) -> 36 | Y15: 13.8 | Z15: =Y15*$H$5 -> 1338.462 | AA15: =Z15*$H$6 -> 588.92328 | AB15: 66.93 | AC15: =Z15+AA15+AB15 -> 1994.3153 | AD15: =X15*AC15 -> 71795.35
B16: RETAIL INTENSIVE AFTERCARE HYDROJELLY MASK 2masks/Box | C16: ='Order Calculation'!B11 -> RETAIL | D16: ='Order Calculation'!C11 | E16: ='Order Calculation'!D11 -> 1 | F16: ='Order Calculation'!E11 -> 10 | G16: ='Order Calculation'!F11 | H16: ='Order Calculation'!G11 -> 1 | I16: ='Order Calculation'!H11 -> 1 | J16: ='Order Calculation'!I11 -> 1 | ... R16: ='Order Calculation'!Q11 | S16: ='Order Calculation'!V11/6 -> 3.6666667 | T16: =S16*$D$5 -> 11 | U16: =S16*$D$6 -> 5.5 | V16: =ROUNDUP(T16+U16,0) -> 17 | W16: ='Order Calculation'!Y11 -> 9 | X16: =MAX(0,V16-W16) -> 8 | Y16: 11.1 | Z16: =Y16*$H$5 -> 1076.589 | AA16: =Z16*$H$6 -> 473.69916 | AB16: 21.53 | AC16: =Z16+AA16+AB16 -> 1571.8182 | AD16: =X16*AC16 -> 12574.545
B17: Measuring Cup | C17: ='Order Calculation'!B52 -> Accessory | D17: ='Order Calculation'!C52 -> 10 | E17: ='Order Calculation'!D52 -> 78 | F17: ='Order Calculation'!E52 -> 38 | G17: ='Order Calculation'!F52 -> 33 | H17: ='Order Calculation'!G52 -> 25 | I17: ='Order Calculation'!H52 -> 28 | J17: ='Order Calculation'!I52 -> 15 | ... R17: ='Order Calculation'!Q52 -> 17 | S17: ='Order Calculation'!V52/6 -> 19 | T17: =V17*0.7 -> 245 | U17: =V17*0.3 -> 105 | V17: 350 | W17: ='Order Calculation'!Y52 -> 239 | X17: =MAX(0,V17-W17) -> 111 | Z17: =Y17*$H$5 -> 0 | AA17: =Z17*$H$6 -> 0 | AB17: 66.93 | AC17: =Z17+AA17+AB17 -> 66.93 | AD17: =X17*AC17 -> 7429.23
B18: WHITE MIXING BOWL | C18: ='Order Calculation'!B51 -> Accessory | D18: ='Order Calculation'!C51 -> 2 | E18: ='Order Calculation'!D51 -> 19 | F18: ='Order Calculation'!E51 -> 9 | G18: ='Order Calculation'!F51 -> 13 | H18: ='Order Calculation'!G51 -> 9 | I18: ='Order Calculation'!H51 -> 11 | J18: ='Order Calculation'!I51 -> 2 | ... R18: ='Order Calculation'!Q51 -> 10 | S18: ='Order Calculation'!V51/6 -> 6.6666667 | T18: =V18*0.7 -> 70 | U18: =V18*0.3 -> 30 | V18: 100 | W18: ='Order Calculation'!Y51 -> 145 | X18: =MAX(0,V18-W18) -> 0 | Z18: =Y18*$H$5 -> 0 | AA18: =Z18*$H$6 -> 0 | AB18: 66.93 | AC18: =Z18+AA18+AB18 -> 66.93 | AD18: =X18*AC18 -> 0
B19: RETAIL EGYPTIAN ROSE HYDROJELLY MASK 2masks/Box | C19: ='Order Calculation'!B50 -> RETAIL | D19: ='Order Calculation'!C50 | E19: ='Order Calculation'!D50 -> 3 | F19: ='Order Calculation'!E50 -> 10 | G19: ='Order Calculation'!F50 -> 20 | H19: ='Order Calculation'!G50 -> 6 | I19: ='Order Calculation'!H50 -> 3 | J19: ='Order Calculation'!I50 -> 1 | ... R19: ='Order Calculation'!Q50 | S19: ='Order Calculation'!V50/6 -> 0 | T19: =S19*$D$5 -> 0 | U19: =S19*$D$6 -> 0 | V19: =ROUNDUP(T19+U19,0) -> 0 | W19: ='Order Calculation'!Y50 -> 110 | X19: =MAX(0,V19-W19) -> 0 | Y19: 11.1 | Z19: =Y19*$H$5 -> 1076.589 | AA19: =Z19*$H$6 -> 473.69916 | AB19: 21.53 | AC19: =Z19+AA19+AB19 -> 1571.8182 | AD19: =X19*AC19 -> 0
B20: Silicone Brush | C20: ='Order Calculation'!B49 -> Accessory | D20: ='Order Calculation'!C49 | E20: ='Order Calculation'!D49 | F20: ='Order Calculation'!E49 -> 1 | G20: ='Order Calculation'!F49 -> 1 | H20: ='Order Calculation'!G49 | I20: ='Order Calculation'!H49 | J20: ='Order Calculation'!I49 | ... R20: ='Order Calculation'!Q49 | S20: ='Order Calculation'!V49/6 -> 0.33333333 | T20: =S20*$D$5 -> 1 | U20: =S20*$D$6 -> 0.5 | V20: =ROUNDUP(T20+U20,0) -> 2 | W20: ='Order Calculation'!Y49 -> 155 | X20: =MAX(0,V20-W20) -> 0 | Z20: =Y20*$H$5 -> 0 | AA20: =Z20*$H$6 -> 0 | AB20: 66.93 | AC20: =Z20+AA20+AB20 -> 66.93 | AD20: =X20*AC20 -> 0
B21: RETAIL ANTIOXIDANT GOJI HYDROJELLY MASK 2masks/Box | C21: ='Order Calculation'!B48 -> RETAIL | D21: ='Order Calculation'!C48 | E21: ='Order Calculation'!D48 -> 1 | F21: ='Order Calculation'!E48 -> 5 | G21: ='Order Calculation'!F48 -> 13 | H21: ='Order Calculation'!G48 -> 1 | I21: ='Order Calculation'!H48 -> 1 | J21: ='Order Calculation'!I48 -> 1 | ... R21: ='Order Calculation'!Q48 | S21: ='Order Calculation'!V48/6 -> 1.3333333 | T21: =S21*$D$5 -> 4 | U21: =S21*$D$6 -> 2 | V21: =ROUNDUP(T21+U21,0) -> 6 | W21: ='Order Calculation'!Y48 -> 102 | X21: =MAX(0,V21-W21) -> 0 | Y21: 11.1 | Z21: =Y21*$H$5 -> 1076.589 | AA21: =Z21*$H$6 -> 473.69916 | AB21: 21.53 | AC21: =Z21+AA21+AB21 -> 1571.8182 | AD21: =X21*AC21 -> 0
B22: RETAIL ILLUMINATING ORANGE HYDROJELLY MASK 2masks/Box | C22: ='Order Calculation'!B47 -> RETAIL | D22: ='Order Calculation'!C47 | E22: ='Order Calculation'!D47 -> 1 | F22: ='Order Calculation'!E47 -> 10 | G22: ='Order Calculation'!F47 -> 6 | H22: ='Order Calculation'!G47 -> 5 | I22: ='Order Calculation'!H47 | J22: ='Order Calculation'!I47 -> 1 | ... R22: ='Order Calculation'!Q47 | S22: ='Order Calculation'!V47/6 -> 3.8333333 | T22: =S22*$D$5 -> 11.5 | U22: =S22*$D$6 -> 5.75 | V22: =ROUNDUP(T22+U22,0) -> 18 | W22: ='Order Calculation'!Y47 -> 102 | X22: =MAX(0,V22-W22) -> 0 | Y22: 11.1 | Z22: =Y22*$H$5 -> 1076.589 | AA22: =Z22*$H$6 -> 473.69916 | AB22: 21.53 | AC22: =Z22+AA22+AB22 -> 1571.8182 | AD22: =X22*AC22 -> 0
B23: RETAIL BRIGHTENING COMPLEX HYDROJELLY MASK 2masks/Box | C23: ='Order Calculation'!B46 -> RETAIL | D23: ='Order Calculation'!C46 -> 1 | E23: ='Order Calculation'!D46 -> 1 | F23: ='Order Calculation'!E46 -> 5 | G23: ='Order Calculation'!F46 -> 14 | H23: ='Order Calculation'!G46 -> 2 | I23: ='Order Calculation'!H46 -> 6 | J23: ='Order Calculation'!I46 -> 1 | ... R23: ='Order Calculation'!Q46 -> 2 | S23: ='Order Calculation'!V46/6 -> 2 | T23: =S23*$D$5 -> 6 | U23: =S23*$D$6 -> 3 | V23: =ROUNDUP(T23+U23,0) -> 9 | W23: ='Order Calculation'!Y46 -> 102 | X23: =MAX(0,V23-W23) -> 0 | Y23: 11.1 | Z23: =Y23*$H$5 -> 1076.589 | AA23: =Z23*$H$6 -> 473.69916 | AB23: 21.53 | AC23: =Z23+AA23+AB23 -> 1571.8182 | AD23: =X23*AC23 -> 0
B24: SPATULA WHITE | C24: ='Order Calculation'!B45 -> Accessory | D24: ='Order Calculation'!C45 -> 2 | E24: ='Order Calculation'!D45 -> 18 | F24: ='Order Calculation'!E45 -> 10 | G24: ='Order Calculation'!F45 -> 13 | H24: ='Order Calculation'!G45 -> 9 | I24: ='Order Calculation'!H45 -> 11 | J24: ='Order Calculation'!I45 -> 2 | ... R24: ='Order Calculation'!Q45 -> 10 | S24: ='Order Calculation'!V45/6 -> 6.6666667 | T24: =V24*0.7 -> 70 | U24: =V24*0.3 -> 30 | V24: 100 | W24: ='Order Calculation'!Y45 -> 149 | X24: =MAX(0,V24-W24) -> 0 | Z24: =Y24*$H$5 -> 0 | AA24: =Z24*$H$6 -> 0 | AB24: 66.93 | AC24: =Z24+AA24+AB24 -> 66.93 | AD24: =X24*AC24 -> 0
B25: PHYTO-NUTRIENTS BLAST HYDROJELLY MASK 850gm | C25: ='Order Calculation'!B44 -> JAR | D25: ='Order Calculation'!C44 -> 2 | E25: ='Order Calculation'!D44 -> 3 | F25: ='Order Calculation'!E44 | G25: ='Order Calculation'!F44 -> 1 | H25: ='Order Calculation'!G44 | I25: ='Order Calculation'!H44 -> 2 | J25: ='Order Calculation'!I44 -> 1 | ... R25: ='Order Calculation'!Q44 | S25: ='Order Calculation'!V44/6 -> 1.1666667 | T25: =S25*$D$5 -> 3.5 | U25: =S25*$D$6 -> 1.75 | V25: =ROUNDUP(T25+U25,0) -> 6 | W25: ='Order Calculation'!Y44 -> 71 | X25: =MAX(0,V25-W25) -> 0 | Y25: 13.8 | Z25: =Y25*$H$5 -> 1338.462 | AA25: =Z25*$H$6 -> 588.92328 | AB25: 66.93 | AC25: =Z25+AA25+AB25 -> 1994.3153 | AD25: =X25*AC25 -> 0
B26: ANTIOXIDANT GOJI HYDROJELLY MASK 850gm | C26: ='Order Calculation'!B43 -> JAR | D26: ='Order Calculation'!C43 -> 4 | E26: ='Order Calculation'!D43 -> 28 | F26: ='Order Calculation'!E43 -> 19 | G26: ='Order Calculation'!F43 -> 20 | H26: ='Order Calculation'!G43 -> 17 | I26: ='Order Calculation'!H43 -> 30 | J26: ='Order Calculation'!I43 -> 21 | ... R26: ='Order Calculation'!Q43 -> 20 | S26: ='Order Calculation'!V43/6 -> 19 | T26: =S26*$D$5 -> 57 | U26: =S26*$D$6 -> 28.5 | V26: =ROUNDUP(T26+U26,0) -> 86 | W26: ='Order Calculation'!Y43 -> 130 | X26: =MAX(0,V26-W26) -> 0 | Y26: 13.8 | Z26: =Y26*$H$5 -> 1338.462 | AA26: =Z26*$H$6 -> 588.92328 | AB26: 66.93 | AC26: =Z26+AA26+AB26 -> 1994.3153 | AD26: =X26*AC26 -> 0
B27: Rose Quartz Eye Mask | C27: ='Order Calculation'!B42 -> Accessory | D27: ='Order Calculation'!C42 -> 2 | E27: ='Order Calculation'!D42 -> 5 | F27: ='Order Calculation'!E42 -> 4 | G27: ='Order Calculation'!F42 -> 5 | H27: ='Order Calculation'!G42 -> 2 | I27: ='Order Calculation'!H42 -> 3 | J27: ='Order Calculation'!I42 | ... R27: ='Order Calculation'!Q42 -> 1 | S27: ='Order Calculation'!V42/6 -> 1 | T27: =V27*0.7 -> 21 | U27: =V27*0.3 -> 9 | V27: 30 | W27: ='Order Calculation'!Y42 -> 83 | X27: =MAX(0,V27-W27) -> 0 | Z27: =Y27*$H$5 -> 0 | AA27: =Z27*$H$6 -> 0 | AB27: 66.93 | AC27: =Z27+AA27+AB27 -> 66.93 | AD27: =X27*AC27 -> 0
B28: CBD DOPE HYDROJELLY MASK 850gm | C28: ='Order Calculation'!B41 -> JAR | D28: ='Order Calculation'!C41 -> 3 | E28: ='Order Calculation'!D41 -> 5 | F28: ='Order Calculation'!E41 -> 12 | G28: ='Order Calculation'!F41 -> 3 | H28: ='Order Calculation'!G41 | I28: ='Order Calculation'!H41 -> 3 | J28: ='Order Calculation'!I41 | ... R28: ='Order Calculation'!Q41 | S28: ='Order Calculation'!V41/6 -> 1.6666667 | T28: =S28*$D$5 -> 5 | U28: =S28*$D$6 -> 2.5 | V28: =ROUNDUP(T28+U28,0) -> 8 | W28: ='Order Calculation'!Y41 -> 67 | X28: =MAX(0,V28-W28) -> 0 | Y28: 24 | Z28: =Y28*$H$5 -> 2327.76 | AA28: =Z28*$H$6 -> 1024.2144 | AB28: 66.93 | AC28: =Z28+AA28+AB28 -> 3418.9044 | AD28: =X28*AC28 -> 0
B29: SUPER GREENS STRENGTH HYDROJELLY MASK 850gm | C29: ='Order Calculation'!B40 -> JAR | D29: ='Order Calculation'!C40 -> 3 | E29: ='Order Calculation'!D40 -> 5 | F29: ='Order Calculation'!E40 -> 11 | G29: ='Order Calculation'!F40 -> 6 | H29: ='Order Calculation'!G40 -> 2 | I29: ='Order Calculation'!H40 -> 3 | J29: ='Order Calculation'!I40 -> 1 | ... R29: ='Order Calculation'!Q40 -> 5 | S29: ='Order Calculation'!V40/6 -> 3.5 | T29: =S29*$D$5 -> 10.5 | U29: =S29*$D$6 -> 5.25 | V29: =ROUNDUP(T29+U29,0) -> 16 | W29: ='Order Calculation'!Y40 -> 65 | X29: =MAX(0,V29-W29) -> 0 | Y29: 13.8 | Z29: =Y29*$H$5 -> 1338.462 | AA29: =Z29*$H$6 -> 588.92328 | AB29: 66.93 | AC29: =Z29+AA29+AB29 -> 1994.3153 | AD29: =X29*AC29 -> 0
B30: RADIANCE BIOTIN HYDROJELLY MASK 850gm | C30: ='Order Calculation'!B39 -> JAR | D30: ='Order Calculation'!C39 -> 2 | E30: ='Order Calculation'!D39 -> 3 | F30: ='Order Calculation'!E39 -> 9 | G30: ='Order Calculation'!F39 -> 1 | H30: ='Order Calculation'!G39 -> 1 | I30: ='Order Calculation'!H39 -> 1 | J30: ='Order Calculation'!I39 -> 1 | ... R30: ='Order Calculation'!Q39 -> 1 | S30: ='Order Calculation'!V39/6 -> 1.3333333 | T30: =S30*$D$5 -> 4 | U30: =S30*$D$6 -> 2 | V30: =ROUNDUP(T30+U30,0) -> 6 | W30: ='Order Calculation'!Y39 -> 54 | X30: =MAX(0,V30-W30) -> 0 | Y30: 13.8 | Z30: =Y30*$H$5 -> 1338.462 | AA30: =Z30*$H$6 -> 588.92328 | AB30: 66.93 | AC30: =Z30+AA30+AB30 -> 1994.3153 | AD30: =X30*AC30 -> 0
B31: AUSTRALIAN SHEEP PLACENTA HYDROJELLY MASK 850ml | C31: ='Order Calculation'!B38 -> JAR | D31: ='Order Calculation'!C38 | E31: ='Order Calculation'!D38 -> 5 | F31: ='Order Calculation'!E38 -> 11 | G31: ='Order Calculation'!F38 -> 5 | H31: ='Order Calculation'!G38 -> 5 | I31: ='Order Calculation'!H38 -> 3 | J31: ='Order Calculation'!I38 -> 4 | ... R31: ='Order Calculation'!Q38 | S31: ='Order Calculation'!V38/6 -> 1.5 | T31: =S31*$D$5 -> 4.5 | U31: =S31*$D$6 -> 2.25 | V31: =ROUNDUP(T31+U31,0) -> 7 | W31: ='Order Calculation'!Y38 -> 53 | X31: =MAX(0,V31-W31) -> 0 | Y31: 13.8 | Z31: =Y31*$H$5 -> 1338.462 | AA31: =Z31*$H$6 -> 588.92328 | AB31: 66.93 | AC31: =Z31+AA31+AB31 -> 1994.3153 | AD31: =X31*AC31 -> 0
B32: BETA-CAROTENE HYDROJELLY MASK 850gm | C32: ='Order Calculation'!B37 -> JAR | D32: ='Order Calculation'!C37 -> 1 | E32: ='Order Calculation'!D37 -> 1 | F32: ='Order Calculation'!E37 -> 7 | G32: ='Order Calculation'!F37 -> 2 | H32: ='Order Calculation'!G37 | I32: ='Order Calculation'!H37 | J32: ='Order Calculation'!I37 -> 2 | ... R32: ='Order Calculation'!Q37 | S32: ='Order Calculation'!V37/6 -> 1.1666667 | T32: =S32*$D$5 -> 3.5 | U32: =S32*$D$6 -> 1.75 | V32: =ROUNDUP(T32+U32,0) -> 6 | W32: ='Order Calculation'!Y37 -> 52 | X32: =MAX(0,V32-W32) -> 0 | Y32: 13.8 | Z32: =Y32*$H$5 -> 1338.462 | AA32: =Z32*$H$6 -> 588.92328 | AB32: 66.93 | AC32: =Z32+AA32+AB32 -> 1994.3153 | AD32: =X32*AC32 -> 0
B33: GOLD MIXING BOWL | C33: ='Order Calculation'!B36 -> Accessory | D33: ='Order Calculation'!C36 -> 2 | E33: ='Order Calculation'!D36 -> 14 | F33: ='Order Calculation'!E36 -> 8 | G33: ='Order Calculation'!F36 -> 2 | H33: ='Order Calculation'!G36 -> 6 | I33: ='Order Calculation'!H36 -> 6 | J33: ='Order Calculation'!I36 -> 9 | ... R33: ='Order Calculation'!Q36 -> 1 | S33: ='Order Calculation'!V36/6 -> 3.8333333 | T33: =V33*0.7 -> 35 | U33: =V33*0.3 -> 15 | V33: 50 | W33: ='Order Calculation'!Y36 -> 68 | X33: =MAX(0,V33-W33) -> 0 | Z33: =Y33*$H$5 -> 0 | AA33: =Z33*$H$6 -> 0 | AB33: 66.93 | AC33: =Z33+AA33+AB33 -> 66.93 | AD33: =X33*AC33 -> 0
B34: RETAIL PHYTO NUTRIENTS HYDROJELLY MASK 2masks/Box | C34: ='Order Calculation'!B35 -> RETAIL | D34: ='Order Calculation'!C35 | E34: ='Order Calculation'!D35 -> 1 | F34: ='Order Calculation'!E35 | G34: ='Order Calculation'!F35 | H34: ='Order Calculation'!G35 | I34: ='Order Calculation'!H35 -> 4 | J34: ='Order Calculation'!I35 -> 1 | ... R34: ='Order Calculation'!Q35 | S34: ='Order Calculation'!V35/6 -> 0.33333333 | T34: =S34*$D$5 -> 1 | U34: =S34*$D$6 -> 0.5 | V34: =ROUNDUP(T34+U34,0) -> 2 | W34: ='Order Calculation'!Y35 -> 46 | X34: =MAX(0,V34-W34) -> 0 | Y34: 11.1 | Z34: =Y34*$H$5 -> 1076.589 | AA34: =Z34*$H$6 -> 473.69916 | AB34: 21.53 | AC34: =Z34+AA34+AB34 -> 1571.8182 | AD34: =X34*AC34 -> 0
B35: ROLLING CRYO WHITE GLOBES | C35: ='Order Calculation'!B34 -> Accessory | D35: ='Order Calculation'!C34 | E35: ='Order Calculation'!D34 -> 2 | F35: ='Order Calculation'!E34 -> 1 | G35: ='Order Calculation'!F34 -> 1 | H35: ='Order Calculation'!G34 -> 2 | I35: ='Order Calculation'!H34 -> 1 | J35: ='Order Calculation'!I34 | ... R35: ='Order Calculation'!Q34 | S35: ='Order Calculation'!V34/6 -> 0 | T35: =V35*0.7 -> 21 | U35: =V35*0.3 -> 9 | V35: 30 | W35: ='Order Calculation'!Y34 -> 61 | X35: =MAX(0,V35-W35) -> 0 | Z35: =Y35*$H$5 -> 0 | AA35: =Z35*$H$6 -> 0 | AB35: 66.93 | AC35: =Z35+AA35+AB35 -> 66.93 | AD35: =X35*AC35 -> 0
B36: HYALURONIC ACID HYDROJELLY MASK 850gm | C36: ='Order Calculation'!B33 -> JAR | D36: ='Order Calculation'!C33 -> 2 | E36: ='Order Calculation'!D33 -> 10 | F36: ='Order Calculation'!E33 -> 7 | G36: ='Order Calculation'!F33 -> 9 | H36: ='Order Calculation'!G33 -> 5 | I36: ='Order Calculation'!H33 -> 5 | J36: ='Order Calculation'!I33 -> 3 | ... R36: ='Order Calculation'!Q33 -> 5 | S36: ='Order Calculation'!V33/6 -> 3.5 | T36: =S36*$D$5 -> 10.5 | U36: =S36*$D$6 -> 5.25 | V36: =ROUNDUP(T36+U36,0) -> 16 | W36: ='Order Calculation'!Y33 -> 55 | X36: =MAX(0,V36-W36) -> 0 | Y36: 13.8 | Z36: =Y36*$H$5 -> 1338.462 | AA36: =Z36*$H$6 -> 588.92328 | AB36: 66.93 | AC36: =Z36+AA36+AB36 -> 1994.3153 | AD36: =X36*AC36 -> 0
B37: CICA COMPLEX HYDROJELLY MASK 850gm | C37: ='Order Calculation'!B32 -> JAR | D37: ='Order Calculation'!C32 -> 2 | E37: ='Order Calculation'!D32 -> 10 | F37: ='Order Calculation'!E32 -> 12 | G37: ='Order Calculation'!F32 -> 3 | H37: ='Order Calculation'!G32 -> 1 | I37: ='Order Calculation'!H32 -> 10 | J37: ='Order Calculation'!I32 -> 4 | ... R37: ='Order Calculation'!Q32 -> 6 | S37: ='Order Calculation'!V32/6 -> 6.1666667 | T37: =S37*$D$5 -> 18.5 | U37: =S37*$D$6 -> 9.25 | V37: =ROUNDUP(T37+U37,0) -> 28 | W37: ='Order Calculation'!Y32 -> 60 | X37: =MAX(0,V37-W37) -> 0 | Y37: 13.8 | Z37: =Y37*$H$5 -> 1338.462 | AA37: =Z37*$H$6 -> 588.92328 | AB37: 66.93 | AC37: =Z37+AA37+AB37 -> 1994.3153 | AD37: =X37*AC37 -> 0
B38: RETAIL SKIN WARRIOR AGELESS HYDROJELLY MASK 2masks/Box | C38: ='Order Calculation'!B31 -> RETAIL | D38: ='Order Calculation'!C31 | E38: ='Order Calculation'!D31 -> 1 | F38: ='Order Calculation'!E31 | G38: ='Order Calculation'!F31 | H38: ='Order Calculation'!G31 | I38: ='Order Calculation'!H31 -> 3 | J38: ='Order Calculation'!I31 -> 7 | ... R38: ='Order Calculation'!Q31 | S38: ='Order Calculation'!V31/6 -> 0.66666667 | T38: =S38*$D$5 -> 2 | U38: =S38*$D$6 -> 1 | V38: =ROUNDUP(T38+U38,0) -> 3 | W38: ='Order Calculation'!Y31 -> 39 | X38: =MAX(0,V38-W38) -> 0 | Y38: 11.1 | Z38: =Y38*$H$5 -> 1076.589 | AA38: =Z38*$H$6 -> 473.69916 | AB38: 21.53 | AC38: =Z38+AA38+AB38 -> 1571.8182 | AD38: =X38*AC38 -> 0
B39: PURE HIMALAYAN WHITE TEA HYDROJELLY MASK 850gm | C39: ='Order Calculation'!B30 -> JAR | D39: ='Order Calculation'!C30 -> 5 | E39: ='Order Calculation'!D30 -> 2 | F39: ='Order Calculation'!E30 -> 9 | G39: ='Order Calculation'!F30 -> 7 | H39: ='Order Calculation'!G30 | I39: ='Order Calculation'!H30 -> 2 | J39: ='Order Calculation'!I30 -> 3 | ... R39: ='Order Calculation'!Q30 -> 1 | S39: ='Order Calculation'!V30/6 -> 1.1666667 | T39: =S39*$D$5 -> 3.5 | U39: =S39*$D$6 -> 1.75 | V39: =ROUNDUP(T39+U39,0) -> 6 | W39: ='Order Calculation'!Y30 -> 41 | X39: =MAX(0,V39-W39) -> 0 | Y39: 13.8 | Z39: =Y39*$H$5 -> 1338.462 | AA39: =Z39*$H$6 -> 588.92328 | AB39: 66.93 | AC39: =Z39+AA39+AB39 -> 1994.3153 | AD39: =X39*AC39 -> 0
B40: RETAIL SUPER GREENS STRENGTH HYDROJELLY MASK 2masks/Box | C40: ='Order Calculation'!B29 -> RETAIL | D40: ='Order Calculation'!C29 | E40: ='Order Calculation'!D29 -> 1 | F40: ='Order Calculation'!E29 | G40: ='Order Calculation'!F29 | H40: ='Order Calculation'!G29 | I40: ='Order Calculation'!H29 -> 2 | J40: ='Order Calculation'!I29 -> 4 | ... R40: ='Order Calculation'!Q29 | S40: ='Order Calculation'!V29/6 -> 0.66666667 | T40: =S40*$D$5 -> 2 | U40: =S40*$D$6 -> 1 | V40: =ROUNDUP(T40+U40,0) -> 3 | W40: ='Order Calculation'!Y29 -> 40 | X40: =MAX(0,V40-W40) -> 0 | Y40: 11.1 | Z40: =Y40*$H$5 -> 1076.589 | AA40: =Z40*$H$6 -> 473.69916 | AB40: 21.53 | AC40: =Z40+AA40+AB40 -> 1571.8182 | AD40: =X40*AC40 -> 0
B41: ROLLING CRYO PINK GLOBES | C41: ='Order Calculation'!B28 -> Accessory | D41: ='Order Calculation'!C28 | E41: ='Order Calculation'!D28 -> 5 | F41: ='Order Calculation'!E28 | G41: ='Order Calculation'!F28 -> 3 | H41: ='Order Calculation'!G28 | I41: ='Order Calculation'!H28 | J41: ='Order Calculation'!I28 | ... R41: ='Order Calculation'!Q28 | S41: ='Order Calculation'!V28/6 -> 0.33333333 | T41: =V41*0.7 -> 21 | U41: =V41*0.3 -> 9 | V41: 30 | W41: ='Order Calculation'!Y28 -> 53 | X41: =MAX(0,V41-W41) -> 0 | Z41: =Y41*$H$5 -> 0 | AA41: =Z41*$H$6 -> 0 | AB41: 66.93 | AC41: =Z41+AA41+AB41 -> 66.93 | AD41: =X41*AC41 -> 0
B42: VAMPIRE INFUSION HYDROJELLY MASK 850gm | C42: ='Order Calculation'!B27 -> JAR | D42: ='Order Calculation'!C27 -> 1 | E42: ='Order Calculation'!D27 -> 13 | F42: ='Order Calculation'!E27 -> 15 | G42: ='Order Calculation'!F27 -> 6 | H42: ='Order Calculation'!G27 -> 11 | I42: ='Order Calculation'!H27 -> 13 | J42: ='Order Calculation'!I27 -> 7 | ... R42: ='Order Calculation'!Q27 -> 2 | S42: ='Order Calculation'!V27/6 -> 5.1666667 | T42: =S42*$D$5 -> 15.5 | U42: =S42*$D$6 -> 7.75 | V42: =ROUNDUP(T42+U42,0) -> 24 | W42: ='Order Calculation'!Y27 -> 52 | X42: =MAX(0,V42-W42) -> 0 | Y42: 13.8 | Z42: =Y42*$H$5 -> 1338.462 | AA42: =Z42*$H$6 -> 588.92328 | AB42: 66.93 | AC42: =Z42+AA42+AB42 -> 1994.3153 | AD42: =X42*AC42 -> 0
B43: RETAIL CICA COMPLEX HYDROJELLY MASK 2masks/Box | C43: ='Order Calculation'!B26 -> RETAIL | D43: ='Order Calculation'!C26 | E43: ='Order Calculation'!D26 -> 3 | F43: ='Order Calculation'!E26 | G43: ='Order Calculation'!F26 -> 2 | H43: ='Order Calculation'!G26 -> 1 | I43: ='Order Calculation'!H26 -> 2 | J43: ='Order Calculation'!I26 -> 4 | ... R43: ='Order Calculation'!Q26 | S43: ='Order Calculation'!V26/6 -> 0.66666667 | T43: =S43*$D$5 -> 2 | U43: =S43*$D$6 -> 1 | V43: =ROUNDUP(T43+U43,0) -> 3 | W43: ='Order Calculation'!Y26 -> 37 | X43: =MAX(0,V43-W43) -> 0 | Y43: 11.1 | Z43: =Y43*$H$5 -> 1076.589 | AA43: =Z43*$H$6 -> 473.69916 | AB43: 21.53 | AC43: =Z43+AA43+AB43 -> 1571.8182 | AD43: =X43*AC43 -> 0
B44: PURIFYING CHARCOAL HYDROJELLY MASK 850gm | C44: ='Order Calculation'!B25 -> JAR | D44: ='Order Calculation'!C25 -> 6 | E44: ='Order Calculation'!D25 -> 12 | F44: ='Order Calculation'!E25 -> 14 | G44: ='Order Calculation'!F25 -> 18 | H44: ='Order Calculation'!G25 -> 11 | I44: ='Order Calculation'!H25 -> 5 | J44: ='Order Calculation'!I25 -> 3 | ... R44: ='Order Calculation'!Q25 -> 6 | S44: ='Order Calculation'!V25/6 -> 4.8333333 | T44: =S44*$D$5 -> 14.5 | U44: =S44*$D$6 -> 7.25 | V44: =ROUNDUP(T44+U44,0) -> 22 | W44: ='Order Calculation'!Y25 -> 51 | X44: =MAX(0,V44-W44) -> 0 | Y44: 13.8 | Z44: =Y44*$H$5 -> 1338.462 | AA44: =Z44*$H$6 -> 588.92328 | AB44: 66.93 | AC44: =Z44+AA44+AB44 -> 1994.3153 | AD44: =X44*AC44 -> 0
...

Sheet Order Calculation
C1: 1 | D1: 2 | E1: 3 | F1: 4 | G1: 5 | H1: 6 | I1: 7 | J1: 8 | K1: 9 | L1: 10 | M1: 11 | N1: 12 | O1: 13 | P1: 14 | Q1: 15 | T1: Total
A2: Esthemax Product | B2: Catagaory | C2: 45748 | D2: 45778 | E2: 45809 | F2: 45839 | G2: 45870 | H2: 45901 | I2: 45931 | J2: 45962 | K2: 45992 | L2: 46023 | M2: 46054 | N2: 46082 | O2: 46113 | P2: 46143 | Q2: 46174 | R2: ESTIMATE 3 MONTH STOCK REQUIRED FOR SALON AND SPA | S2: Internal use | T2: Last 15 month Average | U2: Last 12 month Average | V2: last 6 month sum | W2: Last 3 Monthly Average | X2: 3 month order | Y2: Current stock | Z2: Diffrence | AA2: Orde
A3: ILLUMINATING ORANGE HYDROJELLY MASK 850gm | B3: JAR | C3: 5 | D3: 70 | E3: 38 | F3: 18 | G3: 41 | H3: 19 | I3: 13 | J3: 47 | K3: 59 | L3: 34 | M3: 44 | N3: 12 | O3: 29 | P3: 45 | Q3: 55 | S3: 5 | T3: =SUM(C3:Q3)/15 -> 35.266667 | U3: =SUM(F3:Q3)/12 -> 34.666667 | V3: =SUM(L3:Q3) -> 219 | W3: =SUM(O3:Q3)/3 -> 43 | X3: =W3*3 -> 129 | Y3: 28 | Z3: =X3-Y3 -> 101 | AA3: =MAX(0,(X3+S3+N(R3))-Y3) -> 106
A4: EGYPTIAN ROSE HYDROJELLY MASK 850gm | B4: JAR | C4: 9 | D4: 86 | E4: 32 | F4: 60 | G4: 14 | H4: 31 | I4: 22 | J4: 57 | K4: 51 | L4: 41 | M4: 53 | N4: 23 | O4: 46 | P4: 35 | Q4: 32 | S4: 5 | T4: =SUM(C4:Q4)/15 -> 39.466667 | U4: =SUM(F4:Q4)/12 -> 38.75 | V4: =SUM(L4:Q4) -> 230 | W4: =SUM(O4:Q4)/3 -> 37.666667 | X4: =W4*3 -> 113 | Y4: 64 | Z4: =X4-Y4 -> 49 | AA4: =MAX(0,(X4+S4+N(R4))-Y4) -> 54
A5: Sample BAGS | B5: SAMPLE | S5: 100 | T5: =SUM(C5:Q5)/15 -> 0 | U5: =SUM(F5:Q5)/12 -> 0 | V5: =SUM(L5:Q5) -> 0 | W5: =SUM(O5:Q5)/3 -> 0 | X5: =W5*3 -> 0 | Y5: 49 | Z5: =X5-Y5 -> -49 | AA5: =MAX(0,(X5+S5+N(R5))-Y5) -> 51
A6: Small Spatula (Plastic) | B6: Accessory | D6: 1 | S6: 50 | T6: =SUM(C6:Q6)/15 -> 0.066666667 | U6: =SUM(F6:Q6)/12 -> 0 | V6: =SUM(L6:Q6) -> 0 | W6: =SUM(O6:Q6)/3 -> 0 | X6: =W6*3 -> 0 | Y6: 0 | Z6: =X6-Y6 -> 0 | AA6: =MAX(0,(X6+S6+N(R6))-Y6) -> 50
A7: INTENSIVE AFTERCARE HYDROJELLY MASK 850gm | B7: JAR | C7: 2 | D7: 20 | E7: 17 | F7: 22 | G7: 12 | H7: 23 | I7: 4 | J7: 20 | K7: 12 | L7: 9 | M7: 11 | N7: 10 | O7: 12 | P7: 17 | Q7: 11 | S7: 5 | T7: =SUM(C7:Q7)/15 -> 13.466667 | U7: =SUM(F7:Q7)/12 -> 13.583333 | V7: =SUM(L7:Q7) -> 70 | W7: =SUM(O7:Q7)/3 -> 13.333333 | X7: =W7*3 -> 40 | Y7: 1 | Z7: =X7-Y7 -> 39 | AA7: =MAX(0,(X7+S7+N(R7))-Y7) -> 44
A8: BELGIUM CACAO HYDROJELLY MASK 850gm | B8: JAR | C8: 17 | D8: 9 | E8: 20 | F8: 5 | G8: 15 | H8: 1 | I8: 3 | J8: 16 | K8: 22 | L8: 1 | M8: 22 | N8: 4 | O8: 27 | P8: 3 | Q8: 4 | S8: 5 | T8: =SUM(C8:Q8)/15 -> 11.266667 | U8: =SUM(F8:Q8)/12 -> 10.25 | V8: =SUM(L8:Q8) -> 61 | W8: =SUM(O8:Q8)/3 -> 11.333333 | X8: =W8*3 -> 34 | Y8: 5 | Z8: =X8-Y8 -> 29 | AA8: =MAX(0,(X8+S8+N(R8))-Y8) -> 34
A9: SPATULA HOT PINK | B9: Accessory | C9: 4 | D9: 19 | E9: 13 | F9: 9 | G9: 3 | H9: 13 | I9: 4 | J9: 9 | K9: 10 | L9: 3 | M9: 8 | N9: 10 | O9: 4 | P9: 3 | Q9: 3 | S9: 50 | T9: =SUM(C9:Q9)/15 -> 7.6666667 | U9: =SUM(F9:Q9)/12 -> 6.5833333 | V9: =SUM(L9:Q9) -> 31 | W9: =SUM(O9:Q9)/3 -> 3.3333333 | X9: =W9*3 -> 10 | Y9: 45 | Z9: =X9-Y9 -> -35 | AA9: =MAX(0,(X9+S9+N(R9))-Y9) -> 15
A10: SPATULA NEON GREEN | B10: Accessory | C10: 2 | D10: 21 | E10: 9 | F10: 8 | G10: 4 | H10: 8 | J10: 5 | K10: 6 | L10: 3 | M10: 6 | N10: 3 | O10: 6 | P10: 6 | Q10: 3 | S10: 50 | T10: =SUM(C10:Q10)/15 -> 6 | U10: =SUM(F10:Q10)/12 -> 4.8333333 | V10: =SUM(L10:Q10) -> 27 | W10: =SUM(O10:Q10)/3 -> 5 | X10: =W10*3 -> 15 | Y10: 60 | Z10: =X10-Y10 -> -45 | AA10: =MAX(0,(X10+S10+N(R10))-Y10) -> 5
A11: RETAIL INTENSIVE AFTERCARE HYDROJELLY MASK 2masks/Box | B11: RETAIL | D11: 1 | E11: 10 | G11: 1 | H11: 1 | I11: 1 | J11: 1 | L11: 13 | O11: 1 | P11: 8 | S11: 5 | T11: =SUM(C11:Q11)/15 -> 2.4666667 | U11: =SUM(F11:Q11)/12 -> 2.1666667 | V11: =SUM(L11:Q11) -> 22 | W11: =SUM(O11:Q11)/3 -> 3 | X11: =W11*3 -> 9 | Y11: 9 | Z11: =X11-Y11 -> 0 | AA11: =MAX(0,(X11+S11+N(R11))-Y11) -> 5
A12: RETAIL HYALURONIC ACID HYDROJELLY MASK 2masks/Box | B12: RETAIL | D12: 1 | E12: 8 | F12: 1 | G12: 3 | I12: 1 | P12: 6 | Q12: 3 | S12: 5 | T12: =SUM(C12:Q12)/15 -> 1.5333333 | U12: =SUM(F12:Q12)/12 -> 1.1666667 | V12: =SUM(L12:Q12) -> 9 | W12: =SUM(O12:Q12)/3 -> 3 | X12: =W12*3 -> 9 | Y12: 10 | Z12: =X12-Y12 -> -1 | AA12: =MAX(0,(X12+S12+N(R12))-Y12) -> 4
A13: YOUTHFUL ELIXIR HYDROJELLY MASK 850gm | B13: JAR | C13: 34 | D13: 36 | E13: 16 | F13: 38 | G13: 23 | H13: 5 | I13: 6 | J13: 56 | K13: 29 | L13: 19 | M13: 31 | N13: 19 | O13: 23 | P13: 4 | Q13: 21 | S13: 5 | T13: =SUM(C13:Q13)/15 -> 24 | U13: =SUM(F13:Q13)/12 -> 22.833333 | V13: =SUM(L13:Q13) -> 117 | W13: =SUM(O13:Q13)/3 -> 16 | X13: =W13*3 -> 48 | Y13: 57 | Z13: =X13-Y13 -> -9 | AA13: =MAX(0,(X13+S13+N(R13))-Y13) -> 0
A14: SPATULA GOLD | B14: Accessory | C14: 2 | D14: 14 | E14: 6 | F14: 2 | G14: 6 | H14: 6 | I14: 9 | J14: 6 | K14: 4 | L14: 4 | M14: 6 | N14: 7 | O14: 2 | P14: 3 | Q14: 1 | S14: 50 | T14: =SUM(C14:Q14)/15 -> 5.2 | U14: =SUM(F14:Q14)/12 -> 4.6666667 | V14: =SUM(L14:Q14) -> 23 | W14: =SUM(O14:Q14)/3 -> 2 | X14: =W14*3 -> 6 | Y14: 62 | Z14: =X14-Y14 -> -56 | AA14: =MAX(0,(X14+S14+N(R14))-Y14) -> 0
A15: SPOT DIMINISHING ALA HYDROJELLY MASK 850gm | B15: JAR | C15: 3 | D15: 25 | E15: 10 | F15: 10 | G15: 2 | H15: 16 | I15: 7 | J15: 10 | K15: 15 | L15: 3 | M15: 14 | N15: 8 | O15: 3 | P15: 23 | Q15: 3 | S15: 5 | T15: =SUM(C15:Q15)/15 -> 10.133333 | U15: =SUM(F15:Q15)/12 -> 9.5 | V15: =SUM(L15:Q15) -> 54 | W15: =SUM(O15:Q15)/3 -> 9.6666667 | X15: =W15*3 -> 29 | Y15: 42 | Z15: =X15-Y15 -> -13 | AA15: =MAX(0,(X15+S15+N(R15))-Y15) -> 0
A16: Rose Quartz Full Face Mask | B16: Accessory | D16: 2 | F16: 2 | G16: 1 | S16: 20 | T16: =SUM(C16:Q16)/15 -> 0.33333333 | U16: =SUM(F16:Q16)/12 -> 0.25 | V16: =SUM(L16:Q16) -> 0 | W16: =SUM(O16:Q16)/3 -> 0 | X16: =W16*3 -> 0 | Y16: 30 | Z16: =X16-Y16 -> -30 | AA16: =MAX(0,(X16+S16+N(R16))-Y16) -> 0
A17: RETAIL PURIFYING CHARCOAL HYDROJELLY MASK 2masks/Box | B17: RETAIL | D17: 1 | E17: 5 | F17: 5 | H17: 10 | K17: 3 | M17: 1 | P17: 6 | S17: 5 | T17: =SUM(C17:Q17)/15 -> 2.0666667 | U17: =SUM(F17:Q17)/12 -> 2.0833333 | V17: =SUM(L17:Q17) -> 7 | W17: =SUM(O17:Q17)/3 -> 2 | X17: =W17*3 -> 6 | Y17: 22 | Z17: =X17-Y17 -> -16 | AA17: =MAX(0,(X17+S17+N(R17))-Y17) -> 0
A18: BRIGHTENING COMPLEX HYDROJELLY MASK 850gm | B18: JAR | C18: 5 | D18: 53 | E18: 25 | F18: 35 | G18: 20 | H18: 36 | I18: 12 | J18: 28 | K18: 29 | L18: 16 | M18: 22 | N18: 56 | O18: 44 | P18: 18 | Q18: 10 | S18: 5 | T18: =SUM(C18:Q18)/15 -> 27.266667 | U18: =SUM(F18:Q18)/12 -> 27.166667 | V18: =SUM(L18:Q18) -> 166 | W18: =SUM(O18:Q18)/3 -> 24 | X18: =W18*3 -> 72 | Y18: 89 | Z18: =X18-Y18 -> -17 | AA18: =MAX(0,(X18+S18+N(R18))-Y18) -> 0
A19: Natural Sponge | B19: Accessory | E19: 1 | S19: 50 | T19: =SUM(C19:Q19)/15 -> 0.066666667 | U19: =SUM(F19:Q19)/12 -> 0 | V19: =SUM(L19:Q19) -> 0 | W19: =SUM(O19:Q19)/3 -> 0 | X19: =W19*3 -> 0 | Y19: 64 | Z19: =X19-Y19 -> -64 | AA19: =MAX(0,(X19+S19+N(R19))-Y19) -> 0
A20: HOT PINK MIXING BOWL | B20: Accessory | C20: 4 | D20: 19 | E20: 12 | F20: 9 | G20: 3 | H20: 13 | I20: 4 | J20: 9 | K20: 10 | L20: 3 | M20: 8 | N20: 10 | O20: 4 | P20: 4 | Q20: 3 | S20: 20 | T20: =SUM(C20:Q20)/15 -> 7.6666667 | U20: =SUM(F20:Q20)/12 -> 6.6666667 | V20: =SUM(L20:Q20) -> 32 | W20: =SUM(O20:Q20)/3 -> 3.6666667 | X20: =W20*3 -> 11 | Y20: 46 | Z20: =X20-Y20 -> -35 | AA20: =MAX(0,(X20+S20+N(R20))-Y20) -> 0
A21: RE-NEWAL HYDROJELLY MASK 850gm | B21: JAR | D21: 2 | E21: 8 | F21: 1 | H21: 1 | I21: 2 | K21: 3 | L21: 1 | P21: 4 | S21: 5 | T21: =SUM(C21:Q21)/15 -> 1.4666667 | U21: =SUM(F21:Q21)/12 -> 1 | V21: =SUM(L21:Q21) -> 5 | W21: =SUM(O21:Q21)/3 -> 1.3333333 | X21: =W21*3 -> 4 | Y21: 30 | Z21: =X21-Y21 -> -26 | AA21: =MAX(0,(X21+S21+N(R21))-Y21) -> 0
A22: SKIN WARRIOR AGELESS HYDROJELLY MASK 850gm | B22: JAR | D22: 4 | E22: 2 | F22: 5 | H22: 1 | I22: 1 | J22: 2 | K22: 8 | L22: 1 | M22: 3 | N22: 1 | O22: 3 | P22: 1 | S22: 5 | T22: =SUM(C22:Q22)/15 -> 2.1333333 | U22: =SUM(F22:Q22)/12 -> 2.1666667 | V22: =SUM(L22:Q22) -> 9 | W22: =SUM(O22:Q22)/3 -> 1.3333333 | X22: =W22*3 -> 4 | Y22: 30 | Z22: =X22-Y22 -> -26 | AA22: =MAX(0,(X22+S22+N(R22))-Y22) -> 0
A23: NEON GREEN MIXING BOWL | B23: Accessory | C23: 2 | D23: 22 | E23: 9 | F23: 8 | G23: 4 | H23: 8 | J23: 5 | K23: 6 | L23: 3 | M23: 6 | N23: 3 | O23: 6 | P23: 6 | Q23: 3 | S23: 20 | T23: =SUM(C23:Q23)/15 -> 6.0666667 | U23: =SUM(F23:Q23)/12 -> 4.8333333 | V23: =SUM(L23:Q23) -> 27 | W23: =SUM(O23:Q23)/3 -> 5 | X23: =W23*3 -> 15 | Y23: 59 | Z23: =X23-Y23 -> -44 | AA23: =MAX(0,(X23+S23+N(R23))-Y23) -> 0
A24: RESILIANCE CAVIAR HYDROJELLY MASK 850ml | B24: JAR | D24: 2 | E24: 5 | F24: 1 | G24: 27 | H24: 1 | I24: 10 | K24: 21 | M24: 1 | O24: 1 | S24: 5 | T24: =SUM(C24:Q24)/15 -> 4.6 | U24: =SUM(F24:Q24)/12 -> 5.1666667 | V24: =SUM(L24:Q24) -> 2 | W24: =SUM(O24:Q24)/3 -> 0.33333333 | X24: =W24*3 -> 1 | Y24: 32 | Z24: =X24-Y24 -> -31 | AA24: =MAX(0,(X24+S24+N(R24))-Y24) -> 0
A25: PURIFYING CHARCOAL HYDROJELLY MASK 850gm | B25: JAR | C25: 6 | D25: 12 | E25: 14 | F25: 18 | G25: 11 | H25: 5 | I25: 3 | J25: 7 | K25: 12 | L25: 1 | M25: 10 | N25: 2 | O25: 9 | P25: 1 | Q25: 6 | S25: 5 | T25: =SUM(C25:Q25)/15 -> 7.8 | U25: =SUM(F25:Q25)/12 -> 7.0833333 | V25: =SUM(L25:Q25) -> 29 | W25: =SUM(O25:Q25)/3 -> 5.3333333 | X25: =W25*3 -> 16 | Y25: 51 | Z25: =X25-Y25 -> -35 | AA25: =MAX(0,(X25+S25+N(R25))-Y25) -> 0
A26: RETAIL CICA COMPLEX HYDROJELLY MASK 2masks/Box | B26: RETAIL | D26: 3 | F26: 2 | G26: 1 | H26: 2 | I26: 4 | K26: 4 | N26: 2 | O26: 1 | P26: 1 | S26: 5 | T26: =SUM(C26:Q26)/15 -> 1.3333333 | U26: =SUM(F26:Q26)/12 -> 1.4166667 | V26: =SUM(L26:Q26) -> 4 | W26: =SUM(O26:Q26)/3 -> 0.66666667 | X26: =W26*3 -> 2 | Y26: 37 | Z26: =X26-Y26 -> -35 | AA26: =MAX(0,(X26+S26+N(R26))-Y26) -> 0
A27: VAMPIRE INFUSION HYDROJELLY MASK 850gm | B27: JAR | C27: 1 | D27: 13 | E27: 15 | F27: 6 | G27: 11 | H27: 13 | I27: 7 | J27: 14 | K27: 4 | L27: 6 | M27: 7 | N27: 2 | P27: 14 | Q27: 2 | S27: 5 | T27: =SUM(C27:Q27)/15 -> 7.6666667 | U27: =SUM(F27:Q27)/12 -> 7.1666667 | V27: =SUM(L27:Q27) -> 31 | W27: =SUM(O27:Q27)/3 -> 5.3333333 | X27: =W27*3 -> 16 | Y27: 52 | Z27: =X27-Y27 -> -36 | AA27: =MAX(0,(X27+S27+N(R27))-Y27) -> 0
A28: ROLLING CRYO PINK GLOBES | B28: Accessory | D28: 5 | F28: 3 | K28: 1 | M28: 1 | O28: 1 | S28: 20 | T28: =SUM(C28:Q28)/15 -> 0.73333333 | U28: =SUM(F28:Q28)/12 -> 0.5 | V28: =SUM(L28:Q28) -> 2 | W28: =SUM(O28:Q28)/3 -> 0.33333333 | X28: =W28*3 -> 1 | Y28: 53 | Z28: =X28-Y28 -> -52 | AA28: =MAX(0,(X28+S28+N(R28))-Y28) -> 0
A29: RETAIL SUPER GREENS STRENGTH HYDROJELLY MASK 2masks/Box | B29: RETAIL | D29: 1 | H29: 2 | I29: 4 | K29: 6 | L29: 1 | P29: 3 | S29: 5 | T29: =SUM(C29:Q29)/15 -> 1.1333333 | U29: =SUM(F29:Q29)/12 -> 1.3333333 | V29: =SUM(L29:Q29) -> 4 | W29: =SUM(O29:Q29)/3 -> 1 | X29: =W29*3 -> 3 | Y29: 40 | Z29: =X29-Y29 -> -37 | AA29: =MAX(0,(X29+S29+N(R29))-Y29) -> 0
A30: PURE HIMALAYAN WHITE TEA HYDROJELLY MASK 850gm | B30: JAR | C30: 5 | D30: 2 | E30: 9 | F30: 7 | H30: 2 | I30: 3 | J30: 1 | K30: 3 | M30: 2 | N30: 2 | P30: 2 | Q30: 1 | S30: 5 | T30: =SUM(C30:Q30)/15 -> 2.6 | U30: =SUM(F30:Q30)/12 -> 1.9166667 | V30: =SUM(L30:Q30) -> 7 | W30: =SUM(O30:Q30)/3 -> 1 | X30: =W30*3 -> 3 | Y30: 41 | Z30: =X30-Y30 -> -38 | AA30: =MAX(0,(X30+S30+N(R30))-Y30) -> 0
A31: RETAIL SKIN WARRIOR AGELESS HYDROJELLY MASK 2masks/Box | B31: RETAIL | D31: 1 | H31: 3 | I31: 7 | K31: 1 | L31: 2 | N31: 1 | P31: 1 | S31: 5 | T31: =SUM(C31:Q31)/15 -> 1.0666667 | U31: =SUM(F31:Q31)/12 -> 1.25 | V31: =SUM(L31:Q31) -> 4 | W31: =SUM(O31:Q31)/3 -> 0.33333333 | X31: =W31*3 -> 1 | Y31: 39 | Z31: =X31-Y31 -> -38 | AA31: =MAX(0,(X31+S31+N(R31))-Y31) -> 0
A32: CICA COMPLEX HYDROJELLY MASK 850gm | B32: JAR | C32: 2 | D32: 10 | E32: 12 | F32: 3 | G32: 1 | H32: 10 | I32: 4 | J32: 7 | K32: 9 | L32: 10 | M32: 4 | N32: 2 | O32: 13 | P32: 2 | Q32: 6 | S32: 5 | T32: =SUM(C32:Q32)/15 -> 6.3333333 | U32: =SUM(F32:Q32)/12 -> 5.9166667 | V32: =SUM(L32:Q32) -> 37 | W32: =SUM(O32:Q32)/3 -> 7 | X32: =W32*3 -> 21 | Y32: 60 | Z32: =X32-Y32 -> -39 | AA32: =MAX(0,(X32+S32+N(R32))-Y32) -> 0
A33: HYALURONIC ACID HYDROJELLY MASK 850gm | B33: JAR | C33: 2 | D33: 10 | E33: 7 | F33: 9 | G33: 5 | H33: 5 | I33: 3 | J33: 9 | K33: 55 | L33: 4 | M33: 3 | N33: 2 | O33: 3 | P33: 4 | Q33: 5 | S33: 5 | T33: =SUM(C33:Q33)/15 -> 8.4 | U33: =SUM(F33:Q33)/12 -> 8.9166667 | V33: =SUM(L33:Q33) -> 21 | W33: =SUM(O33:Q33)/3 -> 4 | X33: =W33*3 -> 12 | Y33: 55 | Z33: =X33-Y33 -> -43 | AA33: =MAX(0,(X33+S33+N(R33))-Y33) -> 0
A34: ROLLING CRYO WHITE GLOBES | B34: Accessory | D34: 2 | E34: 1 | F34: 1 | G34: 2 | H34: 1 | S34: 20 | T34: =SUM(C34:Q34)/15 -> 0.46666667 | U34: =SUM(F34:Q34)/12 -> 0.33333333 | V34: =SUM(L34:Q34) -> 0 | W34: =SUM(O34:Q34)/3 -> 0 | X34: =W34*3 -> 0 | Y34: 61 | Z34: =X34-Y34 -> -61 | AA34: =MAX(0,(X34+S34+N(R34))-Y34) -> 0
A35: RETAIL PHYTO NUTRIENTS HYDROJELLY MASK 2masks/Box | B35: RETAIL | D35: 1 | H35: 4 | I35: 1 | K35: 3 | L35: 1 | N35: 1 | S35: 5 | T35: =SUM(C35:Q35)/15 -> 0.73333333 | U35: =SUM(F35:Q35)/12 -> 0.83333333 | V35: =SUM(L35:Q35) -> 2 | W35: =SUM(O35:Q35)/3 -> 0 | X35: =W35*3 -> 0 | Y35: 46 | Z35: =X35-Y35 -> -46 | AA35: =MAX(0,(X35+S35+N(R35))-Y35) -> 0
A36: GOLD MIXING BOWL | B36: Accessory | C36: 2 | D36: 14 | E36: 8 | F36: 2 | G36: 6 | H36: 6 | I36: 9 | J36: 6 | K36: 4 | L36: 4 | M36: 6 | N36: 7 | O36: 2 | P36: 3 | Q36: 1 | S36: 20 | T36: =SUM(C36:Q36)/15 -> 5.3333333 | U36: =SUM(F36:Q36)/12 -> 4.6666667 | V36: =SUM(L36:Q36) -> 23 | W36: =SUM(O36:Q36)/3 -> 2 | X36: =W36*3 -> 6 | Y36: 68 | Z36: =X36-Y36 -> -62 | AA36: =MAX(0,(X36+S36+N(R36))-Y36) -> 0
A37: BETA-CAROTENE HYDROJELLY MASK 850gm | B37: JAR | C37: 1 | D37: 1 | E37: 7 | F37: 2 | I37: 2 | K37: 5 | M37: 2 | N37: 1 | O37: 1 | P37: 3 | S37: 5 | T37: =SUM(C37:Q37)/15 -> 1.6666667 | U37: =SUM(F37:Q37)/12 -> 1.3333333 | V37: =SUM(L37:Q37) -> 7 | W37: =SUM(O37:Q37)/3 -> 1.3333333 | X37: =W37*3 -> 4 | Y37: 52 | Z37: =X37-Y37 -> -48 | AA37: =MAX(0,(X37+S37+N(R37))-Y37) -> 0
A38: AUSTRALIAN SHEEP PLACENTA HYDROJELLY MASK 850ml | B38: JAR | D38: 5 | E38: 11 | F38: 5 | G38: 5 | H38: 3 | I38: 4 | J38: 2 | K38: 3 | L38: 2 | N38: 3 | O38: 2 | P38: 2 | S38: 5 | T38: =SUM(C38:Q38)/15 -> 3.1333333 | U38: =SUM(F38:Q38)/12 -> 2.5833333 | V38: =SUM(L38:Q38) -> 9 | W38: =SUM(O38:Q38)/3 -> 1.3333333 | X38: =W38*3 -> 4 | Y38: 53 | Z38: =X38-Y38 -> -49 | AA38: =MAX(0,(X38+S38+N(R38))-Y38) -> 0
A39: RADIANCE BIOTIN HYDROJELLY MASK 850gm | B39: JAR | C39: 2 | D39: 3 | E39: 9 | F39: 1 | G39: 1 | H39: 1 | I39: 1 | K39: 37 | M39: 3 | N39: 1 | O39: 2 | P39: 1 | Q39: 1 | S39: 5 | T39: =SUM(C39:Q39)/15 -> 4.2 | U39: =SUM(F39:Q39)/12 -> 4.0833333 | V39: =SUM(L39:Q39) -> 8 | W39: =SUM(O39:Q39)/3 -> 1.3333333 | X39: =W39*3 -> 4 | Y39: 54 | Z39: =X39-Y39 -> -50 | AA39: =MAX(0,(X39+S39+N(R39))-Y39) -> 0
A40: SUPER GREENS STRENGTH HYDROJELLY MASK 850gm | B40: JAR | C40: 3 | D40: 5 | E40: 11 | F40: 6 | G40: 2 | H40: 3 | I40: 1 | L40: 2 | M40: 2 | N40: 3 | O40: 2 | P40: 7 | Q40: 5 | S40: 5 | T40: =SUM(C40:Q40)/15 -> 3.4666667 | U40: =SUM(F40:Q40)/12 -> 2.75 | V40: =SUM(L40:Q40) -> 21 | W40: =SUM(O40:Q40)/3 -> 4.6666667 | X40: =W40*3 -> 14 | Y40: 65 | Z40: =X40-Y40 -> -51 | AA40: =MAX(0,(X40+S40+N(R40))-Y40) -> 0
...
